<sdf version='1.6'>
  <world name='default'>
    <light name='sun' type='directional'>
      <cast_shadows>1</cast_shadows>
      <pose frame=''>0 0 10 0 -0 0</pose>
      <diffuse>0.8 0.8 0.8 1</diffuse>
      <specular>0.2 0.2 0.2 1</specular>
      <attenuation>
        <range>1000</range>
        <constant>0.9</constant>
        <linear>0.01</linear>
        <quadratic>0.001</quadratic>
      </attenuation>
      <direction>-0.5 0.1 -0.9</direction>
    </light>
    <model name='ground_plane'>
      <static>1</static>
      <link name='link'>
        <collision name='collision'>
          <geometry>
            <plane>
              <normal>0 0 1</normal>
              <size>100 100</size>
            </plane>
          </geometry>
          <surface>
            <contact>
              <collide_bitmask>65535</collide_bitmask>
              <ode/>
            </contact>
            <friction>
              <ode>
                <mu>100</mu>
                <mu2>50</mu2>
              </ode>
              <torsional>
                <ode/>
              </torsional>
            </friction>
            <bounce/>
          </surface>
          <max_contacts>10</max_contacts>
        </collision>
        <visual name='visual'>
          <cast_shadows>0</cast_shadows>
          <geometry>
            <plane>
              <normal>0 0 1</normal>
              <size>100 100</size>
            </plane>
          </geometry>
          <material>
            <script>
              <uri>file://media/materials/scripts/gazebo.material</uri>
              <name>Gazebo/Grey</name>
            </script>
          </material>
        </visual>
        <self_collide>0</self_collide>
        <enable_wind>0</enable_wind>
        <kinematic>0</kinematic>
      </link>
    </model>
    <gravity>0 0 -9.8</gravity>
    <magnetic_field>6e-06 2.3e-05 -4.2e-05</magnetic_field>
    <atmosphere type='adiabatic'/>
    <physics name='default_physics' default='0' type='ode'>
      <max_step_size>0.001</max_step_size>
      <real_time_factor>1</real_time_factor>
      <real_time_update_rate>1000</real_time_update_rate>
    </physics>
    <scene>
      <ambient>0.4 0.4 0.4 1</ambient>
      <background>0.7 0.7 0.7 1</background>
      <shadows>1</shadows>
    </scene>
    <audio>
      <device>default</device>
    </audio>
    <wind/>
    <spherical_coordinates>
      <surface_model>EARTH_WGS84</surface_model>
      <latitude_deg>0</latitude_deg>
      <longitude_deg>0</longitude_deg>
      <elevation>0</elevation>
      <heading_deg>0</heading_deg>
    </spherical_coordinates>
    <state world_name='default'>
      <sim_time>399 744000000</sim_time>
      <real_time>49 876942955</real_time>
      <wall_time>1587463124 721561525</wall_time>
      <iterations>48132</iterations>
      <model name='ground_plane'>
        <pose frame=''>0 0 0 0 -0 0</pose>
        <scale>1 1 1</scale>
        <link name='link'>
          <pose frame=''>0 0 0 0 -0 0</pose>
          <velocity>0 0 0 0 -0 0</velocity>
          <acceleration>0 0 0 0 -0 0</acceleration>
          <wrench>0 0 0 0 -0 0</wrench>
        </link>
      </model>
      <model name='my_robot'>
        <pose frame=''>0.370518 0.070079 -9e-06 -2e-05 5.7e-05 0.158728</pose>
        <scale>1 1 1</scale>
        <link name='chassis'>
          <pose frame=''>0.370524 0.070081 0.099991 -2e-05 5.7e-05 0.158728</pose>
          <velocity>-0.002714 0.001826 0.000145 0.002616 -0.000746 0.004708</velocity>
          <acceleration>-0.22718 0.241869 0.290567 -1.35294 -1.12044 1.49692</acceleration>
          <wrench>-2.2718 2.41869 2.90567 0 -0 0</wrench>
        </link>
        <link name='left_wheel'>
          <pose frame=''>0.489812 -0.042479 0.1 -1.57066 1.30733 0.158787</pose>
          <velocity>-0.001997 0.00244 -0.002576 0.018142 0.001898 0.0065</velocity>
          <acceleration>-3.41508 4.7244 0.582217 -1.57009 1.36387 -0.671883</acceleration>
          <wrench>-3.41508 4.7244 0.582217 0 -0 0</wrench>
        </link>
        <link name='right_wheel'>
          <pose frame=''>0.448717 0.214254 0.100002 -1.57088 1.07384 0.158597</pose>
          <velocity>-0.003965 0.002145 0.004494 -0.022233 -0.039895 0.001593</velocity>
          <acceleration>5.81283 -6.3171 0.863644 2.25122 -1.40947 -0.688006</acceleration>
          <wrench>5.81283 -6.3171 0.863644 0 -0 0</wrench>
        </link>
        <link name='rplidar::base'>
          <pose frame=''>0.370527 0.070083 0.159991 -2e-05 5.8e-05 0.158728</pose>
          <velocity>-0.002762 0.001653 0.000141 0.00231 -0.000702 0.004663</velocity>
          <acceleration>-0.173855 0.418485 0.280882 -1.66593 -1.40291 1.40555</acceleration>
          <wrench>-0.173855 0.418485 0.280882 0 -0 0</wrench>
        </link>
        <link name='rplidar::top'>
          <pose frame=''>0.370528 0.070084 0.180991 -2.9e-05 5.5e-05 1e-06</pose>
          <velocity>-0.002775 0.001608 0.00013 0.002177 -0.00065 0</velocity>
          <acceleration>-0.199093 0.328914 0.259057 -1.93117 -1.29896 -0.000201</acceleration>
          <wrench>-0.199093 0.328914 0.259057 0 -0 0</wrench>
        </link>
      </model>
      <light name='sun'>
        <pose frame=''>0 0 10 0 -0 0</pose>
      </light>
    </state>
    <gui fullscreen='0'>
      <camera name='user_camera'>
        <pose frame=''>1.25308 -1.26123 0.590181 0 0.275643 2.35619</pose>
        <view_controller>orbit</view_controller>
        <projection_type>perspective</projection_type>
      </camera>
    </gui>
    <model name='my_robot'>
      <static>0</static>
      <link name='chassis'>
        <pose frame=''>0 0 0.1 0 -0 0</pose>
        <inertial>
          <mass>10</mass>
          <pose frame=''>0 0 0.1 0 -0 0</pose>
          <inertia>
            <ixx>0.5</ixx>
            <iyy>1</iyy>
            <izz>0.1</izz>
            <ixy>0</ixy>
            <ixz>0</ixz>
            <iyz>0</iyz>
          </inertia>
        </inertial>
        <collision name='collision'>
          <geometry>
            <box>
              <size>0.4 0.2 0.1</size>
            </box>
          </geometry>
          <max_contacts>10</max_contacts>
          <surface>
            <contact>
              <ode/>
            </contact>
            <bounce/>
            <friction>
              <torsional>
                <ode/>
              </torsional>
              <ode/>
            </friction>
          </surface>
        </collision>
        <visual name='visual'>
          <pose frame=''>0 0 0 0 -0 0</pose>
          <geometry>
            <box>
              <size>0.4 0.2 0.1</size>
            </box>
          </geometry>
        </visual>
        <collision name='caster_collision'>
          <pose frame=''>-0.15 0 -0.05 0 -0 0</pose>
          <geometry>
            <sphere>
              <radius>0.05</radius>
            </sphere>
          </geometry>
          <surface>
            <friction>
              <ode>
                <mu>0</mu>
                <mu2>0</mu2>
                <slip1>1</slip1>
                <slip2>1</slip2>
              </ode>
              <torsional>
                <ode/>
              </torsional>
            </friction>
            <contact>
              <ode/>
            </contact>
            <bounce/>
          </surface>
          <max_contacts>10</max_contacts>
        </collision>
        <visual name='caster_visual'>
          <pose frame=''>-0.15 0 -0.05 0 -0 0</pose>
          <geometry>
            <sphere>
              <radius>0.05</radius>
            </sphere>
          </geometry>
        </visual>
        <self_collide>0</self_collide>
        <enable_wind>0</enable_wind>
        <kinematic>0</kinematic>
      </link>
      <link name='right_wheel'>
        <pose frame=''>0.1 0.13 0.1 -0 1.5707 1.5707</pose>
        <inertial>
          <pose frame=''>0.1 0.13 0.1 -0 1.5707 1.5707</pose>
          <mass>1</mass>
          <inertia>
            <ixx>0.0045</ixx>
            <iyy>0.005</iyy>
            <izz>0.0045</izz>
            <ixy>0</ixy>
            <ixz>0</ixz>
            <iyz>0</iyz>
          </inertia>
        </inertial>
        <collision name='collision'>
          <geometry>
            <cylinder>
              <radius>0.1</radius>
              <length>0.05</length>
            </cylinder>
          </geometry>
          <surface>
            <friction>
              <ode>
                <mu>10</mu>
                <mu2>10</mu2>
              </ode>
              <torsional>
                <ode/>
              </torsional>
            </friction>
            <contact>
              <ode/>
            </contact>
            <bounce/>
          </surface>
          <max_contacts>10</max_contacts>
        </collision>
        <visual name='visual'>
          <geometry>
            <cylinder>
              <radius>0.1</radius>
              <length>0.05</length>
            </cylinder>
          </geometry>
        </visual>
        <self_collide>0</self_collide>
        <enable_wind>0</enable_wind>
        <kinematic>0</kinematic>
      </link>
      <link name='left_wheel'>
        <pose frame=''>0.1 -0.13 0.1 -0 1.5707 1.5707</pose>
        <inertial>
          <pose frame=''>0.1 0.13 0.1 -0 1.5707 1.5707</pose>
          <mass>1</mass>
          <inertia>
            <ixx>0.0045</ixx>
            <iyy>0.005</iyy>
            <izz>0.0045</izz>
            <ixy>0</ixy>
            <ixz>0</ixz>
            <iyz>0</iyz>
          </inertia>
        </inertial>
        <collision name='collision'>
          <geometry>
            <cylinder>
              <radius>0.1</radius>
              <length>0.05</length>
            </cylinder>
          </geometry>
          <surface>
            <friction>
              <ode>
                <mu>10</mu>
                <mu2>10</mu2>
              </ode>
              <torsional>
                <ode/>
              </torsional>
            </friction>
            <contact>
              <ode/>
            </contact>
            <bounce/>
          </surface>
          <max_contacts>10</max_contacts>
        </collision>
        <visual name='visual'>
          <geometry>
            <cylinder>
              <radius>0.1</radius>
              <length>0.05</length>
            </cylinder>
          </geometry>
        </visual>
        <self_collide>0</self_collide>
        <enable_wind>0</enable_wind>
        <kinematic>0</kinematic>
      </link>
      <link name='rplidar::base'>
        <pose frame=''>0 0 0.16 0 -0 0</pose>
        <collision name='base_collision'>
          <geometry>
            <cylinder>
              <radius>0.038</radius>
              <length>0.02</length>
            </cylinder>
          </geometry>
          <max_contacts>10</max_contacts>
          <surface>
            <contact>
              <ode/>
            </contact>
            <bounce/>
            <friction>
              <torsional>
                <ode/>
              </torsional>
              <ode/>
            </friction>
          </surface>
        </collision>
        <visual name='base_visual'>
          <geometry>
            <cylinder>
              <radius>0.038</radius>
              <length>0.02</length>
            </cylinder>
          </geometry>
        </visual>
        <self_collide>0</self_collide>
        <inertial>
          <inertia>
            <ixx>1</ixx>
            <ixy>0</ixy>
            <ixz>0</ixz>
            <iyy>1</iyy>
            <iyz>0</iyz>
            <izz>1</izz>
          </inertia>
          <mass>1</mass>
        </inertial>
        <enable_wind>0</enable_wind>
        <kinematic>0</kinematic>
      </link>
      <link name='rplidar::top'>
        <sensor name='sensor' type='ray'>
          <pose frame=''>0 0 0.002 0 -0 1.5707</pose>
          <visualize>1</visualize>
          <topic>range</topic>
          <update_rate>30</update_rate>
          <ray>
            <noise>
              <type>gaussian</type>
              <mean>0</mean>
              <stddev>0.02</stddev>
            </noise>
            <scan>
              <horizontal>
                <samples>120</samples>
                <resolution>1</resolution>
                <min_angle>0</min_angle>
                <max_angle>6.28</max_angle>
              </horizontal>
              <vertical>
                <samples>1</samples>
                <min_angle>0</min_angle>
                <max_angle>0</max_angle>
              </vertical>
            </scan>
            <range>
              <min>0.15</min>
              <max>12</max>
              <resolution>0.02</resolution>
            </range>
          </ray>
          <plugin name='sensor_plugin' filename='libgazebo_ros_laser.so'>
            <topicName>/my_car/rplidar/scan</topicName>
            <frameName>/my_robot/odom</frameName>
          </plugin>
        </sensor>
        <pose frame=''>0 0 0.181 0 -0 0</pose>
        <collision name='top_collision'>
          <geometry>
            <cylinder>
              <radius>0.038</radius>
              <length>0.02</length>
            </cylinder>
          </geometry>
          <max_contacts>10</max_contacts>
          <surface>
            <contact>
              <ode/>
            </contact>
            <bounce/>
            <friction>
              <torsional>
                <ode/>
              </torsional>
              <ode/>
            </friction>
          </surface>
        </collision>
        <visual name='top_visual'>
          <geometry>
            <cylinder>
              <radius>0.038</radius>
              <length>0.02</length>
            </cylinder>
          </geometry>
        </visual>
        <self_collide>0</self_collide>
        <inertial>
          <inertia>
            <ixx>1</ixx>
            <ixy>0</ixy>
            <ixz>0</ixz>
            <iyy>1</iyy>
            <iyz>0</iyz>
            <izz>1</izz>
          </inertia>
          <mass>1</mass>
        </inertial>
        <enable_wind>0</enable_wind>
        <kinematic>0</kinematic>
      </link>
      <joint name='rplidar::joint' type='revolute'>
        <pose frame=''>0 0 -0.016 0 -0 0</pose>
        <parent>rplidar::base</parent>
        <child>rplidar::top</child>
        <axis>
          <xyz>0 0 1</xyz>
          <limit>
            <lower>-1e+16</lower>
            <upper>1e+16</upper>
          </limit>
          <use_parent_model_frame>0</use_parent_model_frame>
          <dynamics>
            <spring_reference>0</spring_reference>
            <spring_stiffness>0</spring_stiffness>
          </dynamics>
        </axis>
      </joint>
      <joint name='rplidar_joint' type='fixed'>
        <child>rplidar::base</child>
        <parent>chassis</parent>
      </joint>
      <joint name='left_wheel_joint' type='revolute'>
        <pose frame=''>0 0 -0.03 0 -0 0</pose>
        <child>left_wheel</child>
        <parent>chassis</parent>
        <axis>
          <xyz>0 1 0</xyz>
          <use_parent_model_frame>1</use_parent_model_frame>
          <limit>
            <lower>-1e+16</lower>
            <upper>1e+16</upper>
          </limit>
          <dynamics>
            <spring_reference>0</spring_reference>
            <spring_stiffness>0</spring_stiffness>
          </dynamics>
        </axis>
      </joint>
      <joint name='right_wheel_joint' type='revolute'>
        <pose frame=''>0 0 0.03 0 -0 0</pose>
        <child>right_wheel</child>
        <parent>chassis</parent>
        <axis>
          <xyz>0 1 0</xyz>
          <use_parent_model_frame>1</use_parent_model_frame>
          <limit>
            <lower>-1e+16</lower>
            <upper>1e+16</upper>
          </limit>
          <dynamics>
            <spring_reference>0</spring_reference>
            <spring_stiffness>0</spring_stiffness>
          </dynamics>
        </axis>
      </joint>
      <plugin name='differential_drive_controller' filename='libgazebo_ros_diff_drive.so'>
        <alwaysOn>1</alwaysOn>
        <updateRate>20</updateRate>
        <leftJoint>left_wheel_joint</leftJoint>
        <rightJoint>right_wheel_joint</rightJoint>
        <wheelSeparation>0.4</wheelSeparation>
        <wheelDiameter>0.1</wheelDiameter>
        <wheelTorque>20</wheelTorque>
        <commandTopic>cmd_vel</commandTopic>
        <odometryTopic>odom</odometryTopic>
        <odometryFrame>odom</odometryFrame>
        <publishTf>1</publishTf>
        <publishWheelJointState>1</publishWheelJointState>
        <robotBaseFrame>chassis</robotBaseFrame>
      </plugin>
      <pose frame=''>0.443299 0.043467 0 0 -0 0</pose>
    </model>
  </world>
</sdf>
