<?xml version="1.0" ?>
<sdf version="1.5">
<model name="rplidar">
<!-- Give the base link a unique name -->
<link name="base">

    <!-- Offset the base by half the lenght of the cylinder -->
    <pose>0 0 0.01 0 0 0</pose>
    
    <collision name="base_collision">
      <geometry>
        <cylinder>
          <!-- Radius and length provided by Slamtec -->
          <radius>0.038</radius>
          <length>0.02</length>
        </cylinder>
      </geometry>
    </collision>

    <!-- The visual is mostly a copy of the collision -->
    <visual name="base_visual">
      <geometry>
        <cylinder>
          <radius>0.038</radius>
          <length>0.02</length>
        </cylinder>
      </geometry>
    </visual>
  </link>
  <!-- Give the base link a unique name -->
  <link name="top">
    <!-- Add a ray sensor, and give it a name -->
    <sensor type="ray" name="sensor">

      <!-- Position the ray sensor based on the specification. Also rotate
          it by 90 degrees around the Z-axis to become Horizontal -->
      <pose>0 0 0.002 0 0 1.5707</pose>

      <!-- Enable visualization to see the rays in the GUI -->
      <visualize>true</visualize>

  <topic>range</topic>

      <!-- Set the update rate of the sensor -->
      <update_rate>30</update_rate>
      <ray>
        <noise>
          <!-- Use gaussian noise -->
          <type>gaussian</type>
          <mean>0.0</mean>
          <stddev>0.02</stddev>
        </noise>

        <!-- The scan element contains the horizontal and vertical beams.
            We are leaving out the vertical beams. -->
        <scan>

          <!-- The horizontal beams -->
          <horizontal>
            <!-- The rplidar has 120 beams(samples) -->
            <samples>120</samples>

            <!-- Resolution is multiplied by samples to determine number of
                simulated beams vs interpolated beams. See:
                <http://sdformat.org/spec?ver=1.6&elem=sensor#horizontal_resolution>
                -->
            <resolution>1</resolution>

            <!-- Minimum angle in radians -->
            <min_angle>0</min_angle>

            <!-- Maximum angle in radians -->
            <max_angle>6.28</max_angle>
          </horizontal>
        </scan>

        <!-- Range defines characteristics of an individual beam -->
        <range>

          <!-- Minimum distance of the beam -->
          <min>0.15</min>

          <!-- Maximum distance of the beam -->
          <max>12</max>

          <!-- Linear resolution of the beam -->
          <resolution>0.02</resolution>
        </range>
      </ray>
      <plugin name="sensor_plugin" filename="libgazebo_ros_laser.so">
    <topicName>/my_car/rplidar/scan</topicName>
    <frameName>/my_robot/odom</frameName>
  </plugin>
    </sensor>


    <!-- Vertically offset the top cylinder by the length of the bottom
        cylinder and half the length of this cylinder. -->
    <pose>0 0 0.031 0 0 0</pose>
    <collision name="top_collision">
      <geometry>
        <cylinder>
          <!-- Radius and length provided by Velodyne -->
          <radius>0.038</radius>
          <length>0.02</length>
        </cylinder>
      </geometry>
    </collision>

    <!-- The visual is mostly a copy of the collision -->
    <visual name="top_visual">
      <geometry>
        <cylinder>
          <radius>0.038</radius>
          <length>0.02</length>
        </cylinder>
      </geometry>
    </visual>
  </link>
  <!-- Each joint must have a unique name -->
  <joint type="revolute" name="joint">
    <!-- Position the joint at the bottom of the top link -->
    <pose>0 0 -0.016 0 0 0</pose>

    <!-- Use the base link as the parent of the joint -->
    <parent>base</parent>

    <!-- Use the top link as the child of the joint -->
    <child>top</child>

    <!-- The axis defines the joint's degree of freedom -->
    <axis>

      <!-- Revolve around the z-axis -->
      <xyz>0 0 1</xyz>

      <!-- Limit refers to the range of motion of the joint -->
      <limit>

        <!-- Use a very large number to indicate a continuous revolution -->
        <lower>-10000000000000000</lower>
        <upper>10000000000000000</upper>
      </limit>
    </axis>
  </joint>
</model>

</sdf>
